/home/ubuntu/anaconda3/lib/python3.6/site-packages/sklearn/feature_extraction/text.py:301: UserWarning: Your stop_words may be inconsistent with your preprocessing. Tokenizing the stop words generated tokens ['abov', 'afterward', 'alon', 'alreadi', 'alway', 'ani', 'anoth', 'anyon', 'anyth', 'anywher', 'becam', 'becaus', 'becom', 'befor', 'besid', 'cri', 'describ', 'dure', 'els', 'elsewher', 'empti', 'everi', 'everyon', 'everyth', 'everywher', 'fifti', 'forti', 'henc', 'hereaft', 'herebi', 'howev', 'hundr', 'inde', 'mani', 'meanwhil', 'moreov', 'nobodi', 'noon', 'noth', 'nowher', 'onc', 'onli', 'otherwis', 'ourselv', 'perhap', 'pleas', 'sever', 'sinc', 'sincer', 'sixti', 'someon', 'someth', 'sometim', 'somewher', 'themselv', 'thenc', 'thereaft', 'therebi', 'therefor', 'togeth', 'twelv', 'twenti', 'veri', 'whatev', 'whenc', 'whenev', 'wherea', 'whereaft', 'wherebi', 'wherev', 'whi', 'yourselv'] not in stop_words.
  'stop_words.' % sorted(inconsistent))
Traceback (most recent call last):
  File "AWS_gbc_cv.py", line 59, in <module>
    gbc_cv_score = cross_val_score(gbc,X_train,y_train,scoring='accuracy',cv=3,n_jobs=-1)
  File "/home/ubuntu/anaconda3/lib/python3.6/site-packages/sklearn/model_selection/_validation.py", line 402, in cross_val_score
    error_score=error_score)
  File "/home/ubuntu/anaconda3/lib/python3.6/site-packages/sklearn/model_selection/_validation.py", line 240, in cross_validate
    for train, test in cv.split(X, y, groups))
  File "/home/ubuntu/anaconda3/lib/python3.6/site-packages/sklearn/externals/joblib/parallel.py", line 930, in __call__
    self.retrieve()
  File "/home/ubuntu/anaconda3/lib/python3.6/site-packages/sklearn/externals/joblib/parallel.py", line 833, in retrieve
    self._output.extend(job.get(timeout=self.timeout))
  File "/home/ubuntu/anaconda3/lib/python3.6/site-packages/sklearn/externals/joblib/_parallel_backends.py", line 521, in wrap_future_result
    return future.result(timeout=timeout)
  File "/home/ubuntu/anaconda3/lib/python3.6/concurrent/futures/_base.py", line 432, in result
    return self.__get_result()
  File "/home/ubuntu/anaconda3/lib/python3.6/concurrent/futures/_base.py", line 384, in __get_result
    raise self._exception
sklearn.externals.joblib.externals.loky.process_executor.TerminatedWorkerError: A worker process managed by the executor was unexpectedly terminated. This could be caused by a segmentation fault while calling the function or by an excessive memory usage causing the Operating System to kill the worker. The exit codes of the workers are {SIGTERM(-15)}
